Workbook
Name A: 'Faturamento RJ'!$A:$B
Name Estacionamento: #REF!
Name SegmentaçãodeDados_Categoria: #N/A
Name SegmentaçãodeDados_Categoria1: #N/A
Name SegmentaçãodeDados_Categoria2: #N/A
Name SegmentaçãodeDados_Categoria3: #N/A
Name SegmentaçãodeDados_Fornecedor: #N/A
Name SegmentaçãodeDados_Fornecedor1: #N/A
Name SegmentaçãodeDados_Fornecedor2: #N/A
Name SegmentaçãodeDados_Fornecedor3: #N/A
Name SegmentaçãodeDados_Mês: #N/A
Name SegmentaçãodeDados_Mês_de_referência_para_faturamento: #N/A
Name SegmentaçãodeDados_Unidade: #N/A
Name SegmentaçãodeDados_Unidade1: #N/A
Name SegmentaçãodeDados_Unidade2: #N/A
Name SegmentaçãodeDados_Unidade3: #N/A

Sheet Unidade
A1: Unidade | B1: Regional UF | C1: Regional PS | D1: Regional RS | E1: Cluster | F1: Portifólio
A2: Bangu Shopping | B2: RJ | C2: Sérgio P. | D2: Joana | E2: 3 | F2: Próprio
A3: Carioca Shopping | B3: RJ | C3: Sérgio P. | D3: Joana | E3: 3 | F3: Próprio
A4: Caxias Shopping | B4: RJ | C4: Sérgio P. | D4: Joana | E4: 2 | F4: Próprio
A5: Independência Shopping | B5: RJ | C5: Sérgio P. | D5: Joana | E5: 1 | F5: Próprio
A6: Norte Shopping | B6: RJ | C6: Sérgio P. | D6: Joana | E6: 4 | F6: Próprio
A7: Passeio Shopping | B7: RJ | C7: Sérgio P. | D7: Joana | E7: 1 | F7: Administrado
A8: Recreio Shopping | B8: RJ | C8: Sérgio P. | D8: Joana | E8: 2 | F8: Administrado
A9: Rio Design Leblon | B9: RJ | C9: Sérgio P. | D9: Joana | E9: 1 | F9: Próprio
A10: Shopping Grande Rio | B10: RJ | C10: Sérgio P. | D10: Joana | E10: 3 | F10: Próprio
A11: Shopping Leblon | B11: RJ | C11: Sérgio P. | D11: Joana | E11: 3 | F11: Próprio
A12: Shopping Vila Velha | B12: RJ | C12: Sérgio P. | D12: Joana | E12: 3 | F12: Próprio

Sheet HC
A1: Cluster | B1: Categoria | C1: HC_Min | D1: HC_Max
A2: 1 | B2: Manutenção | C2: 12 | D2: 18
A3: 2 | B3: Manutenção | C3: 16 | D3: 21
A4: 3 | B4: Manutenção | C4: 21 | D4: 29
A5: 4 | B5: Manutenção | C5: 27 | D5: 38
A6: 1 | B6: PMOC | C6: 2 | D6: 2
A7: 2 | B7: PMOC | C7: 2 | D7: 3
A8: 3 | B8: PMOC | C8: 3 | D8: 4
A9: 4 | B9: PMOC | C9: 5 | D9: 7

Sheet Fornecedor
A1: Fornecedor | B1: Brigada de Incêndio | C1: Estacionamento | D1: Limpeza | E1: Manutenção | F1: PMOC | G1: Portaria | H1: Vigilância | I1: Jardinagem | J1: Ascensorista | K1: Resíduos
A2: Action Fire | B2: FTR | C2: Índigo | D2: Verzani | E2: GPS | F2: Brasanitas | G2: GPS | H2: GPS | I2: Verzani | J2: Liderforte | K2: Império
A3: Agro Rio | B3: Onet | C3: GPS | D3: Brasanitas | E3: Brasanitas | F3: GPS | G3: Verzani | H3: Protege | I3: Flora Rocha | K3: GPS
A4: AgroGarden | B4: Medmais | C4: Brasil Park | D4: GPS | E4: Grupo Opus | F4: Grupo Opus | G4: Resolv | H4: Verzani | I4: C&C | K4: Verzani
A5: Agrotexas | B5: Grupo Altum | C5: Verzani | D5: Nova Rio | E5: Verzani | F5: Sethvac | G5: Veper | H5: Grupo Altum | I5: O Jardineiro | K5: Nova Rio
A6: Ambi Verde | B6: Brasanitas | C6: Parker | D6: Grupo Altum | E6: IMC Saste | F6: Verzani | G6: Grupo JLR | H6: Resolv | I6: Verzani | K6: Reambient
A7: AMPLA Resgate Treinamentos | B7: Proteção | C7: Sinart | D7: Grupo Serval | E7: BP Engenharia | F7: Tecnitest | G7: Protege | H7: Veper | I7: Art Garden | K7: Recicla Engenharia
A8: Art Garden | B8: GPS | D8: Seleto | F8: IMC Saste | G8: Grupo Altum | H8: Seleto | I8: L.F. Pinheiro Crepaldi | K8: Ambiente Verde
A9: Artemp | B9: CTA | D9: Limpcar | F9: PA COSTA | G9: Seleto | H9: Grupo JLR | I9: Seleto | K9: Recicla Engenharia
A10: Auto Park | B10: Viver Treinamentos | D10: SulClean | F10: Masstin | G10: Grupo RCR | H10: Grupo RCR | I10: Cheiro de Mata
A11: BM Serviços de Jardinagem | B11: Primazzia | D11: Pratica Service | F11: Artemp | G11: Primar | H11: GR | I11: AgroGarden
A12: Brasanitas | B12: CM Couto | D12: MAP | F12: Lorenzo | G12: SulClean | H12: SulClean | I12: GSBRU
A13: Brasil Gestão | B13: Solução | D13: LNR | G13: Segurpro | H13: Sioux | I13: Paisagismo Ouro
A14: Brasil Park | B14: Brasil Gestão | G14: GR | H14: Grupo Serval | I14: Vegetal
A15: Bravo Fire | B15: Bravo Fire | G15: Project | H15: Embavig | I15: Leve Paisagismo
A16: C&C | B16: AMPLA Resgate Treinamentos | G16: Protesul | H16: Project | I16: Marcia Novaes Paisagismo
A17: Chácara Phoenix | B17: Action Fire | H17: Sion | I17: Jardinando
A18: Cheiro de Mata | B18: Enseg | H18: Segurpro | I18: Marcia Lima Paisagismo
A19: CM Couto | H19: Protesul | I19: BM Serviços de Jardinagem
A20: Colecta | I20: Ambi Verde
A21: CTA | B21: Variações GPS | C21: Variações Verzani | D21: Variações Brasanitas | E21: Variações Grupo Altum | F21: Variações Seleto | G21: Variações Grupo JLR | I21: Floreada
A22: Embavig | B22: Top Service | C22: Veman | D22: Infralink | E22: Liberdade | F22: Líder | G22: Sudeste | I22: Chácara Phoenix
A23: EMOAR | B23: In Haus | E23: 5 estrelas | F23: Prosper | I23: Agrotexas
A24: Enseg | B24: Vivante | E24: Tecnoguarda | I24: Agro Rio
A25: Flora Rocha | B25: Graber | E25: Tecnoseg | I25: Rena's Paisagismo
A26: Floreada | B26: Sunset | E26: Master | I26: Oficina Jardim
A27: Fluency | B27: Visel | E27: Adversi | I27: Garden Green
A28: FTR | B28: Polo Norte | E28: 5SS | I28: Real Mudas
A29: GEBE Garden | B29: SERVIS
A30: GPS
A31: GR
A32: Grupo Altum
A33: Grupo JLR
A34: Grupo Opus
A35: Grupo RCR
A36: Grupo Serval
A37: GSBRU
A38: IMC Saste
A39: Império
A40: Índigo
...

Sheet Categoria
A1: RJ
A2: Brigada de Incêndio
A3: CAG Lojista
A4: Estacionamento
A5: Estacionamento|Portaria 1 atendente 6x1
A6: Fraldário
A7: Jardinagem
A8: Limpeza
A9: Limpeza - Barra Bonita
A10: Manutenção
A11: Manutenção CAG
A12: PMOC
... A19: Vigilância

Sheet tabShoppingsEmails
A1: Shopping | B1: E-mails consolidados | C1: E-mails teste
A2: Amazonas Shopping | B2: andrezza.gaona@allos.co; karen.lima@allos.co; larissa.enes@allos.co; roberto.filho@allos.co; gregori.saavedra@allos.co; pedro.mendes@allos.co
A3: Shopping da Bahia | B3: leidiane.santos@allos.co; antonio.carvalho@allos.co; jose.azevedo@allos.co; jose.fortes@allos.co; mauricio.cerqueira@allos.co; joeval.souza@allos.co; adolfo.klein@allos.co; adson.santos@allos.co; gilson.souza@allos.co
A4: Bangu Shopping | B4: alex.costa@allos.co; victor.fortunato@allos.co; valeria.grajauskas@allos.co; nathally.santos@allos.co; paulo.assis@allos.co; michele.ramos@allos.co; joana.malheiros@atlasinovacoes.com.br
A5: Boulevard Bauru | B5: kelly.bezerrra@boulevardshoppingbauru.com.br; yumi.leite@boulevardshoppingbauru.com.br; murillo.rosa@boulevardshoppingbauru.com.br; fabio.correa@boulevardshoppingbauru.com.br; higor.carneiro@boulevardshoppingbauru.com.br
A6: Boulevard Belém | B6: yugnarley.cintra@allos.co; jose.alfaia@allos.co; joelma.muniz@allos.co; jaqueline.silva@allos.co; alan.rodriguez@allos.co; favacho.junior@allos.co; ana.deoliveira@allos.co; cinthia.araujo@allos.co
A7: Boulevard BH | B7: carla.costa@allos.co; carla.mairinck@allos.co; davidson.pelolungo@allos.co; mariana.almeida@allos.co; denilson.sanches@allos.co; cassio.costa@allos.co; maressa.oliveira@allos.co
A8: Shopping Campo Grande | B8: wilson.lobo@allos.co; murillo.meyer@allos.co; alexandre.ramos@allos.co; ludimila.machado@allos.co
A9: Shopping Campo Limpo | B9: vania.assis@allos.co; gabriela.queiroz@allos.co; camila.pontes@allos.co; fabio.gurjao@allos.co; silvia.machado@allos.co; ricardo.santos@allos.co; fabio.correa@allos.co
A10: Carioca Shopping | B10: david.souza@allos.co; bruna.wanzeler@allos.co; priscilla.souza@allos.co; julio.spinelli@allos.co; andressa.vieira@allos.co; gd_geop.cariocashopping@allos.co; alessandro.gomes@allos.co
A11: Cariri Shopping | B11: rafaela.portilho@caririshopping.com.br; brenda.brito@caririshopping.com.br; vitoria.silva@caririshopping.com.br; emilly.santos@caririshopping.com.br; ana.andrade@caririshopping.com.br; jesualdo.farias@caririshopping.com.br
A12: Catuaí Shopping Londrina | B12: willian.elsner@allos.co; erminia.wada@allos.co; everton.stock@allos.co; giovani.junior@allos.co; tienne.rezende@allos.co
A13: Catuaí Shopping Maringá | B13: sandra.sakamoto@allos.co; marcelo.mizuta@allos.co; emerson.junior@allos.co; daniela.aldrovande@allos.co; lindomar.freitas@allos.co; jonas.godeny@allos.co elaine.oliveira@allos.co
... A50: Shopping Villa Lobos | B50: renan.mattos@allos.co; rita.silva@allos.co; kathleen.hoveler@allos.co; wellington.novaes@allos.co;alberto.oliveira@allos.co

Sheet Teste
A1: Shopping | B1: E-mails consolidados | C1: E-mails teste
A2: Amazonas Shopping | B2: andrezza.gaona@allos.co; karen.lima@allos.co; larissa.enes@allos.co; roberto.filho@allos.co; gregori.saavedra@allos.co; pedro.mendes@allos.co
A3: Shopping da Bahia | B3: leidiane.santos@allos.co; antonio.carvalho@allos.co; jose.azevedo@allos.co; jose.fortes@allos.co; mauricio.cerqueira@allos.co; joeval.souza@allos.co; adolfo.klein@allos.co; adson.santos@allos.co; gilson.souza@allos.co

Sheet Faturamento RJ
B1: Data de Envio | C1: Enviou/Retornou a Medição? | D1: Unidade | E1: Categoria | F1: Fornecedor | G1: HC Organograma | H1: HC Planilha | I1: Dias Faltas | J1: Horas Atrasos | K1: Valor Planilha | L1: Desconto de faltas solicitado pelo fornecedor | M1: Desconto Falta Validado Atlas | N1: Desconto de atrasos solicitado pelo fornecedor | O1: Desconto Atrasos Validado Atlas | P1: Desconto SLA Mês | Q1: Desconto SLA Retroativo | R1: Desconto Equipamentos | S1: Prêmio Assiduidade | T1: Outros descontos | U1: Vai descontar SLA? | V1: Valor mensal final | W1: Taxa de prorrogação do prazo pagamento | X1: Valor mensal com prorrogação do prazo pagamento | Y1: Retroativo de dissídio | Z1: Parcela (x/x) | AA1: Mês de referência para faturamento | AB1: Mês de emissão da NF | AC1: Extras Solicitado pelo fornecedor | AD1: Valor extras validado Atlas | AE1: Valor NF Extra | AF1: NF enviada sistema? | AG1: Valor NF | AH1: NF ok? | AI1: SEFIP Enviada Sistema? | AJ1: Saving Faltas | AK1: Saving Extras | AL1: Deduções Totais | AM1: Observações | AN1: E-mail
C2: Não | D2: Bangu Shopping | E2: Brigada de Incêndio | F2: FTR | G2: 16 | H2: 12 | I2: 0 | J2: 0 | K2: 77251.409 | L2: 0 | M2: 0 | N2: 0 | O2: 0 | P2: Preenchimento pendente | Q2: 0 | R2: 0 | S2: 0 | T2: 0 | V2: =IFERROR((K2+M2+R2+S2+T2+O2)+IF(U2="Sim",P2+Q2,0),(K2+R2+S2+T2)+IF(U2="Sim",P2+Q2,0)) -> 77251.409 | AA2: 45658 | AB2: {=IFERROR( IF( _xlfn.XLOOKUP( 1, ( ('Condições de Faturamento'!$C$2:$C$1000 = Tab_Faturamento_RJ[[#This Row],[Unidade]]) * ('Condições de Faturamento'!$D$2:$D$1000 = Tab_Faturamento_RJ[[#This Row],[Categoria]]) * ('Condições de Faturamento'!$E$2:$E$1000 = Tab_Faturamento_RJ[[#This Row],[Fornecedor]]) ), 'Condições de Faturamento'!$F$2:$F$1000 ) = "Emissão no mês da prestação do serviço", Tab_Faturamento_RJ[[#This Row],[Mês de referência para faturamento]], DATE( YEAR(Tab_Faturamento_RJ[[#This Row],[Mês de referência para faturamento]]), MONTH(Tab_Faturamento_RJ[[#This Row],[Mês de referência para faturamento]]) + 1, DAY(Tab_Faturamento_RJ[[#This Row],[Mês de referência para faturamento]]) ) ), DATE( YEAR(Tab_Faturamento_RJ[[#This Row],[Mês de referência para faturamento]]), MONTH(Tab_Faturamento_RJ[[#This Row],[Mês de referência para faturamento]]) + 1, DAY(Tab_Faturamento_RJ[[#This Row],[Mês de referência para faturamento]]) ) )} -> 45658 | AJ2: =IFERROR(L2-M2,0) -> 0 | AK2: =AC2-AD2 -> 0 | AL2: =K2-V2 -> 0 | AN2: kaike.costa@atlasinovacoes.com.br
C3: Não | D3: Bangu Shopping | E3: Brigada de Incêndio | F3: FTR | G3: 16 | H3: 12 | I3: Informação pendente | J3: Informação pendente | K3: 77251.409 | L3: 0 | M3: Informação pendente | N3: 0 | O3: Informação pendente | P3: Preenchimento pendente | Q3: 0 | R3: 0 | S3: 0 | T3: 0 | V3: =IFERROR((K3+M3+R3+S3+T3+O3)+IF(U3="Sim",P3+Q3,0),(K3+R3+S3+T3)+IF(U3="Sim",P3+Q3,0)) -> 77251.409 | AA3: 45689 | AB3: {=IFERROR( IF( _xlfn.XLOOKUP( 1, ( ('Condições de Faturamento'!$C$2:$C$1000 = Tab_Faturamento_RJ[[#This Row],[Unidade]]) * ('Condições de Faturamento'!$D$2:$D$1000 = Tab_Faturamento_RJ[[#This Row],[Categoria]]) * ('Condições de Faturamento'!$E$2:$E$1000 = Tab_Faturamento_RJ[[#This Row],[Fornecedor]]) ), 'Condições de Faturamento'!$F$2:$F$1000 ) = "Emissão no mês da prestação do serviço", Tab_Faturamento_RJ[[#This Row],[Mês de referência para faturamento]], DATE( YEAR(Tab_Faturamento_RJ[[#This Row],[Mês de referência para faturamento]]), MONTH(Tab_Faturamento_RJ[[#This Row],[Mês de referência para faturamento]]) + 1, DAY(Tab_Faturamento_RJ[[#This Row],[Mês de referência para faturamento]]) ) ), DATE( YEAR(Tab_Faturamento_RJ[[#This Row],[Mês de referência para faturamento]]), MONTH(Tab_Faturamento_RJ[[#This Row],[Mês de referência para faturamento]]) + 1, DAY(Tab_Faturamento_RJ[[#This Row],[Mês de referência para faturamento]]) ) )} -> 45689 | AJ3: =IFERROR(L3-M3,0) -> 0 | AK3: =AC3-AD3 -> 0 | AL3: =K3-V3 -> 0 | AN3: kaike.costa@atlasinovacoes.com.br
B4: 45748 | C4: Sim | D4: Bangu Shopping | E4: Brigada de Incêndio | F4: FTR | G4: 16 | H4: 12 | I4: 0 | J4: 0 | K4: 77251.409 | L4: 0 | M4: 0 | N4: 0 | O4: 0 | P4: 0 | Q4: 0 | R4: 0 | S4: 0 | T4: 0 | U4: Sim | V4: =IFERROR((K4+M4+R4+S4+T4+O4)+IF(U4="Sim",P4+Q4,0),(K4+R4+S4+T4)+IF(U4="Sim",P4+Q4,0)) -> 77251.409 | AA4: 45717 | AB4: {=IFERROR( IF( _xlfn.XLOOKUP( 1, ( ('Condições de Faturamento'!$C$2:$C$1000 = Tab_Faturamento_RJ[[#This Row],[Unidade]]) * ('Condições de Faturamento'!$D$2:$D$1000 = Tab_Faturamento_RJ[[#This Row],[Categoria]]) * ('Condições de Faturamento'!$E$2:$E$1000 = Tab_Faturamento_RJ[[#This Row],[Fornecedor]]) ), 'Condições de Faturamento'!$F$2:$F$1000 ) = "Emissão no mês da prestação do serviço", Tab_Faturamento_RJ[[#This Row],[Mês de referência para faturamento]], DATE( YEAR(Tab_Faturamento_RJ[[#This Row],[Mês de referência para faturamento]]), MONTH(Tab_Faturamento_RJ[[#This Row],[Mês de referência para faturamento]]) + 1, DAY(Tab_Faturamento_RJ[[#This Row],[Mês de referência para faturamento]]) ) ), DATE( YEAR(Tab_Faturamento_RJ[[#This Row],[Mês de referência para faturamento]]), MONTH(Tab_Faturamento_RJ[[#This Row],[Mês de referência para faturamento]]) + 1, DAY(Tab_Faturamento_RJ[[#This Row],[Mês de referência para faturamento]]) ) )} -> 45717 | AJ4: =IFERROR(L4-M4,0) -> 0 | AK4: =AC4-AD4 -> 0 | AL4: =K4-V4 -> 0 | AN4: kaike.costa@atlasinovacoes.com.br
C5: Não | D5: Bangu Shopping | E5: Brigada de Incêndio | F5: FTR | G5: 16 | H5: 12 | I5: 0 | J5: 0 | K5: 77251.409 | L5: 0 | M5: 0 | N5: 0 | O5: 0 | P5: 0 | Q5: 0 | R5: 0 | S5: 0 | T5: 0 | V5: =IFERROR((K5+M5+R5+S5+T5+O5)+IF(U5="Sim",P5+Q5,0),(K5+R5+S5+T5)+IF(U5="Sim",P5+Q5,0)) -> 77251.409 | AA5: 45748 | AB5: {=IFERROR( IF( _xlfn.XLOOKUP( 1, ( ('Condições de Faturamento'!$C$2:$C$1000 = Tab_Faturamento_RJ[[#This Row],[Unidade]]) * ('Condições de Faturamento'!$D$2:$D$1000 = Tab_Faturamento_RJ[[#This Row],[Categoria]]) * ('Condições de Faturamento'!$E$2:$E$1000 = Tab_Faturamento_RJ[[#This Row],[Fornecedor]]) ), 'Condições de Faturamento'!$F$2:$F$1000 ) = "Emissão no mês da prestação do serviço", Tab_Faturamento_RJ[[#This Row],[Mês de referência para faturamento]], DATE( YEAR(Tab_Faturamento_RJ[[#This Row],[Mês de referência para faturamento]]), MONTH(Tab_Faturamento_RJ[[#This Row],[Mês de referência para faturamento]]) + 1, DAY(Tab_Faturamento_RJ[[#This Row],[Mês de referência para faturamento]]) ) ), DATE( YEAR(Tab_Faturamento_RJ[[#This Row],[Mês de referência para faturamento]]), MONTH(Tab_Faturamento_RJ[[#This Row],[Mês de referência para faturamento]]) + 1, DAY(Tab_Faturamento_RJ[[#This Row],[Mês de referência para faturamento]]) ) )} -> 45748 | AJ5: =IFERROR(L5-M5,0) -> 0 | AK5: =AC5-AD5 -> 0 | AL5: =K5-V5 -> 0 | AN5: kaike.costa@atlasinovacoes.com.br
B6: 45812 | C6: Sim | D6: Bangu Shopping | E6: Brigada de Incêndio | F6: FTR | G6: 16 | H6: 12 | I6: 0 | J6: 0 | K6: 77251.409 | L6: 0 | M6: 0 | N6: 0 | O6: 0 | P6: 0 | Q6: 0 | R6: 0 | S6: 0 | T6: 0 | U6: Não | V6: =IFERROR((K6+M6+R6+S6+T6+O6)+IF(U6="Sim",P6+Q6,0),(K6+R6+S6+T6)+IF(U6="Sim",P6+Q6,0)) -> 77251.409 | AA6: 45778 | AB6: {=IFERROR( IF( _xlfn.XLOOKUP( 1, ( ('Condições de Faturamento'!$C$2:$C$1000 = Tab_Faturamento_RJ[[#This Row],[Unidade]]) * ('Condições de Faturamento'!$D$2:$D$1000 = Tab_Faturamento_RJ[[#This Row],[Categoria]]) * ('Condições de Faturamento'!$E$2:$E$1000 = Tab_Faturamento_RJ[[#This Row],[Fornecedor]]) ), 'Condições de Faturamento'!$F$2:$F$1000 ) = "Emissão no mês da prestação do serviço", Tab_Faturamento_RJ[[#This Row],[Mês de referência para faturamento]], DATE( YEAR(Tab_Faturamento_RJ[[#This Row],[Mês de referência para faturamento]]), MONTH(Tab_Faturamento_RJ[[#This Row],[Mês de referência para faturamento]]) + 1, DAY(Tab_Faturamento_RJ[[#This Row],[Mês de referência para faturamento]]) ) ), DATE( YEAR(Tab_Faturamento_RJ[[#This Row],[Mês de referência para faturamento]]), MONTH(Tab_Faturamento_RJ[[#This Row],[Mês de referência para faturamento]]) + 1, DAY(Tab_Faturamento_RJ[[#This Row],[Mês de referência para faturamento]]) ) )} -> 45778 | AJ6: =IFERROR(L6-M6,0) -> 0 | AK6: =AC6-AD6 -> 0 | AL6: =K6-V6 -> 0 | AN6: kaike.costa@atlasinovacoes.com.br
B7: 45839 | C7: Sim | D7: Bangu Shopping | E7: Brigada de Incêndio | F7: FTR | G7: 16 | H7: 12 | I7: 0 | J7: 0 | K7: 77251.409 | L7: 0 | M7: 0 | N7: 0 | O7: 0 | P7: Preenchimento pendente | Q7: 0 | R7: 0 | S7: 0 | T7: 0 | U7: Não | V7: =IFERROR((K7+M7+R7+S7+T7+O7)+IF(U7="Sim",P7+Q7,0),(K7+R7+S7+T7)+IF(U7="Sim",P7+Q7,0)) -> 77251.409 | AA7: 45809 | AB7: {=IFERROR( IF( _xlfn.XLOOKUP( 1, ( ('Condições de Faturamento'!$C$2:$C$1000 = Tab_Faturamento_RJ[[#This Row],[Unidade]]) * ('Condições de Faturamento'!$D$2:$D$1000 = Tab_Faturamento_RJ[[#This Row],[Categoria]]) * ('Condições de Faturamento'!$E$2:$E$1000 = Tab_Faturamento_RJ[[#This Row],[Fornecedor]]) ), 'Condições de Faturamento'!$F$2:$F$1000 ) = "Emissão no mês da prestação do serviço", Tab_Faturamento_RJ[[#This Row],[Mês de referência para faturamento]], DATE( YEAR(Tab_Faturamento_RJ[[#This Row],[Mês de referência para faturamento]]), MONTH(Tab_Faturamento_RJ[[#This Row],[Mês de referência para faturamento]]) + 1, DAY(Tab_Faturamento_RJ[[#This Row],[Mês de referência para faturamento]]) ) ), DATE( YEAR(Tab_Faturamento_RJ[[#This Row],[Mês de referência para faturamento]]), MONTH(Tab_Faturamento_RJ[[#This Row],[Mês de referência para faturamento]]) + 1, DAY(Tab_Faturamento_RJ[[#This Row],[Mês de referência para faturamento]]) ) )} -> 45809 | AJ7: =IFERROR(L7-M7,0) -> 0 | AK7: =AC7-AD7 -> 0 | AL7: =K7-V7 -> 0 | AN7: kaike.costa@atlasinovacoes.com.br
C8: Não | D8: Bangu Shopping | E8: Brigada de Incêndio | F8: FTR | G8: 16 | H8: 12 | I8: Informação pendente | J8: Informação pendente | K8: 81671.16 | L8: 0 | M8: Informação pendente | N8: 0 | O8: Informação pendente | P8: 0 | Q8: 0 | R8: 0 | S8: 0 | T8: 0 | V8: =IFERROR((K8+M8+R8+S8+T8+O8)+IF(U8="Sim",P8+Q8,0),(K8+R8+S8+T8)+IF(U8="Sim",P8+Q8,0)) -> 81671.16 | AA8: 45870 | AB8: {=IFERROR( IF( _xlfn.XLOOKUP( 1, ( ('Condições de Faturamento'!$C$2:$C$1000 = Tab_Faturamento_RJ[[#This Row],[Unidade]]) * ('Condições de Faturamento'!$D$2:$D$1000 = Tab_Faturamento_RJ[[#This Row],[Categoria]]) * ('Condições de Faturamento'!$E$2:$E$1000 = Tab_Faturamento_RJ[[#This Row],[Fornecedor]]) ), 'Condições de Faturamento'!$F$2:$F$1000 ) = "Emissão no mês da prestação do serviço", Tab_Faturamento_RJ[[#This Row],[Mês de referência para faturamento]], DATE( YEAR(Tab_Faturamento_RJ[[#This Row],[Mês de referência para faturamento]]), MONTH(Tab_Faturamento_RJ[[#This Row],[Mês de referência para faturamento]]) + 1, DAY(Tab_Faturamento_RJ[[#This Row],[Mês de referência para faturamento]]) ) ), DATE( YEAR(Tab_Faturamento_RJ[[#This Row],[Mês de referência para faturamento]]), MONTH(Tab_Faturamento_RJ[[#This Row],[Mês de referência para faturamento]]) + 1, DAY(Tab_Faturamento_RJ[[#This Row],[Mês de referência para faturamento]]) ) )} -> 45870 | AC8: 6699.5705 | AD8: 6699.5705 | AJ8: =IFERROR(L8-M8,0) -> 0 | AK8: =AC8-AD8 -> 0 | AL8: =K8-V8 -> 0 | AN8: kaike.costa@atlasinovacoes.com.br
B9: 45870 | C9: Sim | D9: Bangu Shopping | E9: Brigada de Incêndio | F9: FTR | G9: 16 | H9: 12 | I9: 0 | J9: 0 | K9: 81671.16 | L9: 0 | M9: 0 | N9: 0 | O9: 0 | P9: Preenchimento pendente | Q9: 0 | R9: 0 | S9: 0 | T9: 0 | V9: =IFERROR((K9+M9+R9+S9+T9+O9)+IF(U9="Sim",P9+Q9,0),(K9+R9+S9+T9)+IF(U9="Sim",P9+Q9,0)) -> 81671.16 | AA9: 45839 | AB9: {=IFERROR( IF( _xlfn.XLOOKUP( 1, ( ('Condições de Faturamento'!$C$2:$C$1000 = Tab_Faturamento_RJ[[#This Row],[Unidade]]) * ('Condições de Faturamento'!$D$2:$D$1000 = Tab_Faturamento_RJ[[#This Row],[Categoria]]) * ('Condições de Faturamento'!$E$2:$E$1000 = Tab_Faturamento_RJ[[#This Row],[Fornecedor]]) ), 'Condições de Faturamento'!$F$2:$F$1000 ) = "Emissão no mês da prestação do serviço", Tab_Faturamento_RJ[[#This Row],[Mês de referência para faturamento]], DATE( YEAR(Tab_Faturamento_RJ[[#This Row],[Mês de referência para faturamento]]), MONTH(Tab_Faturamento_RJ[[#This Row],[Mês de referência para faturamento]]) + 1, DAY(Tab_Faturamento_RJ[[#This Row],[Mês de referência para faturamento]]) ) ), DATE( YEAR(Tab_Faturamento_RJ[[#This Row],[Mês de referência para faturamento]]), MONTH(Tab_Faturamento_RJ[[#This Row],[Mês de referência para faturamento]]) + 1, DAY(Tab_Faturamento_RJ[[#This Row],[Mês de referência para faturamento]]) ) )} -> 45839 | AJ9: =IFERROR(L9-M9,0) -> 0 | AK9: =AC9-AD9 -> 0 | AL9: =K9-V9 -> 0 | AN9: kaike.costa@atlasinovacoes.com.br
C10: Não | D10: Bangu Shopping | E10: Brigada de Incêndio | F10: FTR | G10: 16 | H10: 12 | I10: Informação pendente | J10: Informação pendente | K10: 81671.16 | L10: 0 | M10: Informação pendente | N10: 0 | O10: Informação pendente | P10: 0 | Q10: 0 | R10: 0 | S10: 0 | T10: 0 | V10: =IFERROR((K10+M10+R10+S10+T10+O10)+IF(U10="Sim",P10+Q10,0),(K10+R10+S10+T10)+IF(U10="Sim",P10+Q10,0)) -> 81671.16 | AA10: 45901 | AB10: {=IFERROR( IF( _xlfn.XLOOKUP( 1, ( ('Condições de Faturamento'!$C$2:$C$1000 = Tab_Faturamento_RJ[[#This Row],[Unidade]]) * ('Condições de Faturamento'!$D$2:$D$1000 = Tab_Faturamento_RJ[[#This Row],[Categoria]]) * ('Condições de Faturamento'!$E$2:$E$1000 = Tab_Faturamento_RJ[[#This Row],[Fornecedor]]) ), 'Condições de Faturamento'!$F$2:$F$1000 ) = "Emissão no mês da prestação do serviço", Tab_Faturamento_RJ[[#This Row],[Mês de referência para faturamento]], DATE( YEAR(Tab_Faturamento_RJ[[#This Row],[Mês de referência para faturamento]]), MONTH(Tab_Faturamento_RJ[[#This Row],[Mês de referência para faturamento]]) + 1, DAY(Tab_Faturamento_RJ[[#This Row],[Mês de referência para faturamento]]) ) ), DATE( YEAR(Tab_Faturamento_RJ[[#This Row],[Mês de referência para faturamento]]), MONTH(Tab_Faturamento_RJ[[#This Row],[Mês de referência para faturamento]]) + 1, DAY(Tab_Faturamento_RJ[[#This Row],[Mês de referência para faturamento]]) ) )} -> 45901 | AD10: 3497.9 | AJ10: =IFERROR(L10-M10,0) -> 0 | AK10: =AC10-AD10 -> -3497.9 | AL10: =K10-V10 -> 0 | AN10: kaike.costa@atlasinovacoes.com.br
C11: Não | D11: Bangu Shopping | E11: Brigada de Incêndio | F11: FTR | G11: 16 | H11: 12 | I11: Informação pendente | J11: Informação pendente | K11: 81671.16 | M11: Informação pendente | O11: Informação pendente | P11: Preenchimento pendente | V11: =IFERROR((K11+M11+R11+S11+T11+O11)+IF(U11="Sim",P11+Q11,0),(K11+R11+S11+T11)+IF(U11="Sim",P11+Q11,0)) -> 81671.16 | AA11: 45931 | AB11: {=IFERROR( IF( _xlfn.XLOOKUP( 1, ( ('Condições de Faturamento'!$C$2:$C$1000 = Tab_Faturamento_RJ[[#This Row],[Unidade]]) * ('Condições de Faturamento'!$D$2:$D$1000 = Tab_Faturamento_RJ[[#This Row],[Categoria]]) * ('Condições de Faturamento'!$E$2:$E$1000 = Tab_Faturamento_RJ[[#This Row],[Fornecedor]]) ), 'Condições de Faturamento'!$F$2:$F$1000 ) = "Emissão no mês da prestação do serviço", Tab_Faturamento_RJ[[#This Row],[Mês de referência para faturamento]], DATE( YEAR(Tab_Faturamento_RJ[[#This Row],[Mês de referência para faturamento]]), MONTH(Tab_Faturamento_RJ[[#This Row],[Mês de referência para faturamento]]) + 1, DAY(Tab_Faturamento_RJ[[#This Row],[Mês de referência para faturamento]]) ) ), DATE( YEAR(Tab_Faturamento_RJ[[#This Row],[Mês de referência para faturamento]]), MONTH(Tab_Faturamento_RJ[[#This Row],[Mês de referência para faturamento]]) + 1, DAY(Tab_Faturamento_RJ[[#This Row],[Mês de referência para faturamento]]) ) )} -> 45931 | AJ11: =IFERROR(L11-M11,0) -> 0 | AK11: =AC11-AD11 -> 0 | AL11: =K11-V11 -> 0 | AN11: kaike.costa@atlasinovacoes.com.br
B12: 45842 | C12: Sim | D12: Bangu Shopping | E12: Limpeza | F12: Verzani | G12: 65 | H12: 60 | I12: 15 | J12: 0 | K12: 335112.54 | L12: 0 | M12: -2342.01 | N12: 0 | O12: 0 | P12: =-1675.56 -> -1675.56 | Q12: 0 | R12: 0 | S12: 0 | T12: 0 | U12: Sim | V12: =IFERROR((K12+M12+R12+S12+T12+O12)+IF(U12="Sim",P12+Q12,0),(K12+R12+S12+T12)+IF(U12="Sim",P12+Q12,0)) -> 331094.97 | Y12: =126534.36/4 -> 31633.59 | Z12: 3|4 | AA12: 45839 | AB12: {=IFERROR( IF( _xlfn.XLOOKUP( 1, ( ('Condições de Faturamento'!$C$2:$C$1000 = Tab_Faturamento_RJ[[#This Row],[Unidade]]) * ('Condições de Faturamento'!$D$2:$D$1000 = Tab_Faturamento_RJ[[#This Row],[Categoria]]) * ('Condições de Faturamento'!$E$2:$E$1000 = Tab_Faturamento_RJ[[#This Row],[Fornecedor]]) ), 'Condições de Faturamento'!$F$2:$F$1000 ) = "Emissão no mês da prestação do serviço", Tab_Faturamento_RJ[[#This Row],[Mês de referência para faturamento]], DATE( YEAR(Tab_Faturamento_RJ[[#This Row],[Mês de referência para faturamento]]), MONTH(Tab_Faturamento_RJ[[#This Row],[Mês de referência para faturamento]]) + 1, DAY(Tab_Faturamento_RJ[[#This Row],[Mês de referência para faturamento]]) ) ), DATE( YEAR(Tab_Faturamento_RJ[[#This Row],[Mês de referência para faturamento]]), MONTH(Tab_Faturamento_RJ[[#This Row],[Mês de referência para faturamento]]) + 1, DAY(Tab_Faturamento_RJ[[#This Row],[Mês de referência para faturamento]]) ) )} -> 45839 | AJ12: =IFERROR(L12-M12,0) -> 2342.01 | AK12: =AC12-AD12 -> 0 | AL12: =K12-V12 -> 4017.57 | AN12: kaike.costa@atlasinovacoes.com.br
D13: Bangu Shopping | E13: Brigada de Incêndio | F13: FTR | G13: 16 | V13: =IFERROR((K13+M13+R13+S13+T13+O13)+IF(U13="Sim",P13+Q13,0),(K13+R13+S13+T13)+IF(U13="Sim",P13+Q13,0)) -> 0 | AA13: 45962 | AB13: {=IFERROR( IF( _xlfn.XLOOKUP( 1, ( ('Condições de Faturamento'!$C$2:$C$1000 = Tab_Faturamento_RJ[[#This Row],[Unidade]]) * ('Condições de Faturamento'!$D$2:$D$1000 = Tab_Faturamento_RJ[[#This Row],[Categoria]]) * ('Condições de Faturamento'!$E$2:$E$1000 = Tab_Faturamento_RJ[[#This Row],[Fornecedor]]) ), 'Condições de Faturamento'!$F$2:$F$1000 ) = "Emissão no mês da prestação do serviço", Tab_Faturamento_RJ[[#This Row],[Mês de referência para faturamento]], DATE( YEAR(Tab_Faturamento_RJ[[#This Row],[Mês de referência para faturamento]]), MONTH(Tab_Faturamento_RJ[[#This Row],[Mês de referência para faturamento]]) + 1, DAY(Tab_Faturamento_RJ[[#This Row],[Mês de referência para faturamento]]) ) ), DATE( YEAR(Tab_Faturamento_RJ[[#This Row],[Mês de referência para faturamento]]), MONTH(Tab_Faturamento_RJ[[#This Row],[Mês de referência para faturamento]]) + 1, DAY(Tab_Faturamento_RJ[[#This Row],[Mês de referência para faturamento]]) ) )} -> 45962 | AJ13: =IFERROR(L13-M13,0) -> 0 | AK13: =AC13-AD13 -> 0 | AL13: =K13-V13 -> 0 | AN13: kaike.costa@atlasinovacoes.com.br
D14: Bangu Shopping | E14: Brigada de Incêndio | F14: FTR | G14: 16 | V14: =IFERROR((K14+M14+R14+S14+T14+O14)+IF(U14="Sim",P14+Q14,0),(K14+R14+S14+T14)+IF(U14="Sim",P14+Q14,0)) -> 0 | AA14: 45992 | AB14: {=IFERROR( IF( _xlfn.XLOOKUP( 1, ( ('Condições de Faturamento'!$C$2:$C$1000 = Tab_Faturamento_RJ[[#This Row],[Unidade]]) * ('Condições de Faturamento'!$D$2:$D$1000 = Tab_Faturamento_RJ[[#This Row],[Categoria]]) * ('Condições de Faturamento'!$E$2:$E$1000 = Tab_Faturamento_RJ[[#This Row],[Fornecedor]]) ), 'Condições de Faturamento'!$F$2:$F$1000 ) = "Emissão no mês da prestação do serviço", Tab_Faturamento_RJ[[#This Row],[Mês de referência para faturamento]], DATE( YEAR(Tab_Faturamento_RJ[[#This Row],[Mês de referência para faturamento]]), MONTH(Tab_Faturamento_RJ[[#This Row],[Mês de referência para faturamento]]) + 1, DAY(Tab_Faturamento_RJ[[#This Row],[Mês de referência para faturamento]]) ) ), DATE( YEAR(Tab_Faturamento_RJ[[#This Row],[Mês de referência para faturamento]]), MONTH(Tab_Faturamento_RJ[[#This Row],[Mês de referência para faturamento]]) + 1, DAY(Tab_Faturamento_RJ[[#This Row],[Mês de referência para faturamento]]) ) )} -> 45992 | AD14: 2882.57 | AJ14: =IFERROR(L14-M14,0) -> 0 | AK14: =AC14-AD14 -> -2882.57 | AL14: =K14-V14 -> 0 | AN14: kaike.costa@atlasinovacoes.com.br
C15: Sim | D15: Bangu Shopping | E15: Fraldário | F15: Verzani | G15: 2 | H15: 2 | I15: 0 | J15: 0 | K15: =8163.51/30.4375*9 -> 2413.851 | L15: 0 | M15: 0 | N15: 0 | O15: 0 | P15: 0 | Q15: 0 | R15: 0 | S15: 0 | T15: 0 | U15: Sim | V15: =IFERROR((K15+M15+R15+S15+T15+O15)+IF(U15="Sim",P15+Q15,0),(K15+R15+S15+T15)+IF(U15="Sim",P15+Q15,0)) -> 2413.851 | AA15: 45717 | AB15: {=IFERROR( IF( _xlfn.XLOOKUP( 1, ( ('Condições de Faturamento'!$C$2:$C$1000 = Tab_Faturamento_RJ[[#This Row],[Unidade]]) * ('Condições de Faturamento'!$D$2:$D$1000 = Tab_Faturamento_RJ[[#This Row],[Categoria]]) * ('Condições de Faturamento'!$E$2:$E$1000 = Tab_Faturamento_RJ[[#This Row],[Fornecedor]]) ), 'Condições de Faturamento'!$F$2:$F$1000 ) = "Emissão no mês da prestação do serviço", Tab_Faturamento_RJ[[#This Row],[Mês de referência para faturamento]], DATE( YEAR(Tab_Faturamento_RJ[[#This Row],[Mês de referência para faturamento]]), MONTH(Tab_Faturamento_RJ[[#This Row],[Mês de referência para faturamento]]) + 1, DAY(Tab_Faturamento_RJ[[#This Row],[Mês de referência para faturamento]]) ) ), DATE( YEAR(Tab_Faturamento_RJ[[#This Row],[Mês de referência para faturamento]]), MONTH(Tab_Faturamento_RJ[[#This Row],[Mês de referência para faturamento]]) + 1, DAY(Tab_Faturamento_RJ[[#This Row],[Mês de referência para faturamento]]) ) )} -> 45748 | AJ15: =IFERROR(L15-M15,0) -> 0 | AK15: =AC15-AD15 -> 0 | AL15: =K15-V15 -> 0 | AN15: kaike.costa@atlasinovacoes.com.br
B16: 45660 | C16: Sim | D16: Bangu Shopping | E16: Fraldário | F16: Verzani | G16: 2 | H16: 2 | I16: 0 | J16: 0 | K16: 8163.51 | L16: 0 | M16: 0 | N16: 0 | O16: 0 | P16: 0 | Q16: 0 | R16: 0 | S16: 0 | T16: 0 | U16: Não | V16: =IFERROR((K16+M16+R16+S16+T16+O16)+IF(U16="Sim",P16+Q16,0),(K16+R16+S16+T16)+IF(U16="Sim",P16+Q16,0)) -> 8163.51 | AA16: 45658 | AB16: {=IFERROR( IF( _xlfn.XLOOKUP( 1, ( ('Condições de Faturamento'!$C$2:$C$1000 = Tab_Faturamento_RJ[[#This Row],[Unidade]]) * ('Condições de Faturamento'!$D$2:$D$1000 = Tab_Faturamento_RJ[[#This Row],[Categoria]]) * ('Condições de Faturamento'!$E$2:$E$1000 = Tab_Faturamento_RJ[[#This Row],[Fornecedor]]) ), 'Condições de Faturamento'!$F$2:$F$1000 ) = "Emissão no mês da prestação do serviço", Tab_Faturamento_RJ[[#This Row],[Mês de referência para faturamento]], DATE( YEAR(Tab_Faturamento_RJ[[#This Row],[Mês de referência para faturamento]]), MONTH(Tab_Faturamento_RJ[[#This Row],[Mês de referência para faturamento]]) + 1, DAY(Tab_Faturamento_RJ[[#This Row],[Mês de referência para faturamento]]) ) ), DATE( YEAR(Tab_Faturamento_RJ[[#This Row],[Mês de referência para faturamento]]), MONTH(Tab_Faturamento_RJ[[#This Row],[Mês de referência para faturamento]]) + 1, DAY(Tab_Faturamento_RJ[[#This Row],[Mês de referência para faturamento]]) ) )} -> 45689 | AJ16: =IFERROR(L16-M16,0) -> 0 | AK16: =AC16-AD16 -> 0 | AL16: =K16-V16 -> 0 | AN16: kaike.costa@atlasinovacoes.com.br
B17: 45700 | C17: Sim | D17: Bangu Shopping | E17: Fraldário | F17: Verzani | G17: 2 | H17: 2 | I17: 0 | J17: 0 | K17: 8163.51 | L17: 0 | M17: 0 | N17: 0 | O17: 0 | P17: 0 | Q17: 0 | R17: 0 | S17: 0 | T17: 0 | U17: Não | V17: =IFERROR((K17+M17+R17+S17+T17+O17)+IF(U17="Sim",P17+Q17,0),(K17+R17+S17+T17)+IF(U17="Sim",P17+Q17,0)) -> 8163.51 | AA17: 45689 | AB17: {=IFERROR( IF( _xlfn.XLOOKUP( 1, ( ('Condições de Faturamento'!$C$2:$C$1000 = Tab_Faturamento_RJ[[#This Row],[Unidade]]) * ('Condições de Faturamento'!$D$2:$D$1000 = Tab_Faturamento_RJ[[#This Row],[Categoria]]) * ('Condições de Faturamento'!$E$2:$E$1000 = Tab_Faturamento_RJ[[#This Row],[Fornecedor]]) ), 'Condições de Faturamento'!$F$2:$F$1000 ) = "Emissão no mês da prestação do serviço", Tab_Faturamento_RJ[[#This Row],[Mês de referência para faturamento]], DATE( YEAR(Tab_Faturamento_RJ[[#This Row],[Mês de referência para faturamento]]), MONTH(Tab_Faturamento_RJ[[#This Row],[Mês de referência para faturamento]]) + 1, DAY(Tab_Faturamento_RJ[[#This Row],[Mês de referência para faturamento]]) ) ), DATE( YEAR(Tab_Faturamento_RJ[[#This Row],[Mês de referência para faturamento]]), MONTH(Tab_Faturamento_RJ[[#This Row],[Mês de referência para faturamento]]) + 1, DAY(Tab_Faturamento_RJ[[#This Row],[Mês de referência para faturamento]]) ) )} -> 45717 | AJ17: =IFERROR(L17-M17,0) -> 0 | AK17: =AC17-AD17 -> 0 | AL17: =K17-V17 -> 0 | AN17: kaike.costa@atlasinovacoes.com.br
B18: 45700 | C18: Sim | D18: Bangu Shopping | E18: Limpeza | F18: Verzani | G18: 65 | H18: 61 | I18: 9 | J18: 0 | K18: 298159.67 | L18: 0 | M18: -1258.03 | N18: 0 | O18: 0 | P18: -496.93 | Q18: 0 | R18: 0 | S18: 0 | T18: 0 | U18: Sim | V18: =IFERROR((K18+M18+R18+S18+T18+O18)+IF(U18="Sim",P18+Q18,0),(K18+R18+S18+T18)+IF(U18="Sim",P18+Q18,0)) -> 296404.71 | AA18: 45689 | AB18: {=IFERROR( IF( _xlfn.XLOOKUP( 1, ( ('Condições de Faturamento'!$C$2:$C$1000 = Tab_Faturamento_RJ[[#This Row],[Unidade]]) * ('Condições de Faturamento'!$D$2:$D$1000 = Tab_Faturamento_RJ[[#This Row],[Categoria]]) * ('Condições de Faturamento'!$E$2:$E$1000 = Tab_Faturamento_RJ[[#This Row],[Fornecedor]]) ), 'Condições de Faturamento'!$F$2:$F$1000 ) = "Emissão no mês da prestação do serviço", Tab_Faturamento_RJ[[#This Row],[Mês de referência para faturamento]], DATE( YEAR(Tab_Faturamento_RJ[[#This Row],[Mês de referência para faturamento]]), MONTH(Tab_Faturamento_RJ[[#This Row],[Mês de referência para faturamento]]) + 1, DAY(Tab_Faturamento_RJ[[#This Row],[Mês de referência para faturamento]]) ) ), DATE( YEAR(Tab_Faturamento_RJ[[#This Row],[Mês de referência para faturamento]]), MONTH(Tab_Faturamento_RJ[[#This Row],[Mês de referência para faturamento]]) + 1, DAY(Tab_Faturamento_RJ[[#This Row],[Mês de referência para faturamento]]) ) )} -> 45689 | AC18: 6047.1549 | AD18: 6047.1549 | AJ18: =IFERROR(L18-M18,0) -> 1258.03 | AK18: =AC18-AD18 -> 0 | AL18: =K18-V18 -> 1754.96 | AN18: kaike.costa@atlasinovacoes.com.br
B19: 45660 | C19: Sim | D19: Bangu Shopping | E19: Limpeza | F19: Verzani | G19: 65 | H19: 61 | I19: 0 | J19: 184 | K19: 298159.67 | L19: 0 | M19: 0 | N19: 0 | O19: -3445.92 | P19: 0 | Q19: 0 | R19: 0 | S19: 0 | T19: 0 | U19: Sim | V19: =IFERROR((K19+M19+R19+S19+T19+O19)+IF(U19="Sim",P19+Q19,0),(K19+R19+S19+T19)+IF(U19="Sim",P19+Q19,0)) -> 294713.75 | AA19: 45658 | AB19: {=IFERROR( IF( _xlfn.XLOOKUP( 1, ( ('Condições de Faturamento'!$C$2:$C$1000 = Tab_Faturamento_RJ[[#This Row],[Unidade]]) * ('Condições de Faturamento'!$D$2:$D$1000 = Tab_Faturamento_RJ[[#This Row],[Categoria]]) * ('Condições de Faturamento'!$E$2:$E$1000 = Tab_Faturamento_RJ[[#This Row],[Fornecedor]]) ), 'Condições de Faturamento'!$F$2:$F$1000 ) = "Emissão no mês da prestação do serviço", Tab_Faturamento_RJ[[#This Row],[Mês de referência para faturamento]], DATE( YEAR(Tab_Faturamento_RJ[[#This Row],[Mês de referência para faturamento]]), MONTH(Tab_Faturamento_RJ[[#This Row],[Mês de referência para faturamento]]) + 1, DAY(Tab_Faturamento_RJ[[#This Row],[Mês de referência para faturamento]]) ) ), DATE( YEAR(Tab_Faturamento_RJ[[#This Row],[Mês de referência para faturamento]]), MONTH(Tab_Faturamento_RJ[[#This Row],[Mês de referência para faturamento]]) + 1, DAY(Tab_Faturamento_RJ[[#This Row],[Mês de referência para faturamento]]) ) )} -> 45658 | AJ19: =IFERROR(L19-M19,0) -> 0 | AK19: =AC19-AD19 -> 0 | AL19: =K19-V19 -> 3445.92 | AN19: kaike.costa@atlasinovacoes.com.br
B20: 45722 | C20: Sim | D20: Bangu Shopping | E20: Limpeza | F20: Verzani | G20: 65 | H20: 61 | I20: 25 | J20: 0 | K20: 298159.67 | L20: 0 | M20: -3481.45 | N20: 0 | O20: 0 | P20: 0 | Q20: 0 | R20: 0 | S20: 0 | T20: 0 | U20: Sim | V20: =IFERROR((K20+M20+R20+S20+T20+O20)+IF(U20="Sim",P20+Q20,0),(K20+R20+S20+T20)+IF(U20="Sim",P20+Q20,0)) -> 294678.22 | AA20: 45717 | AB20: {=IFERROR( IF( _xlfn.XLOOKUP( 1, ( ('Condições de Faturamento'!$C$2:$C$1000 = Tab_Faturamento_RJ[[#This Row],[Unidade]]) * ('Condições de Faturamento'!$D$2:$D$1000 = Tab_Faturamento_RJ[[#This Row],[Categoria]]) * ('Condições de Faturamento'!$E$2:$E$1000 = Tab_Faturamento_RJ[[#This Row],[Fornecedor]]) ), 'Condições de Faturamento'!$F$2:$F$1000 ) = "Emissão no mês da prestação do serviço", Tab_Faturamento_RJ[[#This Row],[Mês de referência para faturamento]], DATE( YEAR(Tab_Faturamento_RJ[[#This Row],[Mês de referência para faturamento]]), MONTH(Tab_Faturamento_RJ[[#This Row],[Mês de referência para faturamento]]) + 1, DAY(Tab_Faturamento_RJ[[#This Row],[Mês de referência para faturamento]]) ) ), DATE( YEAR(Tab_Faturamento_RJ[[#This Row],[Mês de referência para faturamento]]), MONTH(Tab_Faturamento_RJ[[#This Row],[Mês de referência para faturamento]]) + 1, DAY(Tab_Faturamento_RJ[[#This Row],[Mês de referência para faturamento]]) ) )} -> 45717 | AC20: 4881.8859 | AD20: 4881.8859 | AJ20: =IFERROR(L20-M20,0) -> 3481.45 | AK20: =AC20-AD20 -> 0 | AL20: =K20-V20 -> 3481.45 | AN20: kaike.costa@atlasinovacoes.com.br
B21: 45754 | C21: Sim | D21: Bangu Shopping | E21: Limpeza | F21: Verzani | G21: 65 | H21: 61 | I21: 0 | J21: 0 | K21: 298159.67 | L21: 0 | M21: 0 | N21: 0 | O21: 0 | P21: 0 | Q21: 0 | R21: 0 | S21: 0 | T21: 0 | V21: =IFERROR((K21+M21+R21+S21+T21+O21)+IF(U21="Sim",P21+Q21,0),(K21+R21+S21+T21)+IF(U21="Sim",P21+Q21,0)) -> 298159.67 | AA21: 45748 | AB21: {=IFERROR( IF( _xlfn.XLOOKUP( 1, ( ('Condições de Faturamento'!$C$2:$C$1000 = Tab_Faturamento_RJ[[#This Row],[Unidade]]) * ('Condições de Faturamento'!$D$2:$D$1000 = Tab_Faturamento_RJ[[#This Row],[Categoria]]) * ('Condições de Faturamento'!$E$2:$E$1000 = Tab_Faturamento_RJ[[#This Row],[Fornecedor]]) ), 'Condições de Faturamento'!$F$2:$F$1000 ) = "Emissão no mês da prestação do serviço", Tab_Faturamento_RJ[[#This Row],[Mês de referência para faturamento]], DATE( YEAR(Tab_Faturamento_RJ[[#This Row],[Mês de referência para faturamento]]), MONTH(Tab_Faturamento_RJ[[#This Row],[Mês de referência para faturamento]]) + 1, DAY(Tab_Faturamento_RJ[[#This Row],[Mês de referência para faturamento]]) ) ), DATE( YEAR(Tab_Faturamento_RJ[[#This Row],[Mês de referência para faturamento]]), MONTH(Tab_Faturamento_RJ[[#This Row],[Mês de referência para faturamento]]) + 1, DAY(Tab_Faturamento_RJ[[#This Row],[Mês de referência para faturamento]]) ) )} -> 45748 | AJ21: =IFERROR(L21-M21,0) -> 0 | AK21: =AC21-AD21 -> 0 | AL21: =K21-V21 -> 0 | AN21: kaike.costa@atlasinovacoes.com.br
B22: 45789 | C22: Sim | D22: Bangu Shopping | E22: Limpeza | F22: Verzani | G22: 65 | H22: 61 | I22: 0 | J22: 0 | K22: 298159.67 | L22: 0 | M22: 0 | N22: 0 | O22: 0 | P22: 0 | Q22: 0 | R22: 0 | S22: 0 | T22: 0 | U22: Sim | V22: =IFERROR((K22+M22+R22+S22+T22+O22)+IF(U22="Sim",P22+Q22,0),(K22+R22+S22+T22)+IF(U22="Sim",P22+Q22,0)) -> 298159.67 | Y22: =126534.36/4 -> 31633.59 | Z22: 1|4 | AA22: 45778 | AB22: {=IFERROR( IF( _xlfn.XLOOKUP( 1, ( ('Condições de Faturamento'!$C$2:$C$1000 = Tab_Faturamento_RJ[[#This Row],[Unidade]]) * ('Condições de Faturamento'!$D$2:$D$1000 = Tab_Faturamento_RJ[[#This Row],[Categoria]]) * ('Condições de Faturamento'!$E$2:$E$1000 = Tab_Faturamento_RJ[[#This Row],[Fornecedor]]) ), 'Condições de Faturamento'!$F$2:$F$1000 ) = "Emissão no mês da prestação do serviço", Tab_Faturamento_RJ[[#This Row],[Mês de referência para faturamento]], DATE( YEAR(Tab_Faturamento_RJ[[#This Row],[Mês de referência para faturamento]]), MONTH(Tab_Faturamento_RJ[[#This Row],[Mês de referência para faturamento]]) + 1, DAY(Tab_Faturamento_RJ[[#This Row],[Mês de referência para faturamento]]) ) ), DATE( YEAR(Tab_Faturamento_RJ[[#This Row],[Mês de referência para faturamento]]), MONTH(Tab_Faturamento_RJ[[#This Row],[Mês de referência para faturamento]]) + 1, DAY(Tab_Faturamento_RJ[[#This Row],[Mês de referência para faturamento]]) ) )} -> 45778 | AJ22: =IFERROR(L22-M22,0) -> 0 | AK22: =AC22-AD22 -> 0 | AL22: =K22-V22 -> 0 | AN22: kaike.costa@atlasinovacoes.com.br
B23: 45903 | C23: Sim | D23: Bangu Shopping | E23: Limpeza | F23: Verzani | G23: 65 | H23: 60 | I23: 23 | J23: 0 | K23: 335112.54 | L23: 0 | M23: -3167.48 | N23: 0 | O23: 0 | P23: -3351.13 | Q23: 0 | R23: 0 | S23: 0 | T23: 0 | U23: Sim | V23: =IFERROR((K23+M23+R23+S23+T23+O23)+IF(U23="Sim",P23+Q23,0),(K23+R23+S23+T23)+IF(U23="Sim",P23+Q23,0)) -> 328593.93 | AA23: 45901 | AB23: {=IFERROR( IF( _xlfn.XLOOKUP( 1, ( ('Condições de Faturamento'!$C$2:$C$1000 = Tab_Faturamento_RJ[[#This Row],[Unidade]]) * ('Condições de Faturamento'!$D$2:$D$1000 = Tab_Faturamento_RJ[[#This Row],[Categoria]]) * ('Condições de Faturamento'!$E$2:$E$1000 = Tab_Faturamento_RJ[[#This Row],[Fornecedor]]) ), 'Condições de Faturamento'!$F$2:$F$1000 ) = "Emissão no mês da prestação do serviço", Tab_Faturamento_RJ[[#This Row],[Mês de referência para faturamento]], DATE( YEAR(Tab_Faturamento_RJ[[#This Row],[Mês de referência para faturamento]]), MONTH(Tab_Faturamento_RJ[[#This Row],[Mês de referência para faturamento]]) + 1, DAY(Tab_Faturamento_RJ[[#This Row],[Mês de referência para faturamento]]) ) ), DATE( YEAR(Tab_Faturamento_RJ[[#This Row],[Mês de referência para faturamento]]), MONTH(Tab_Faturamento_RJ[[#This Row],[Mês de referência para faturamento]]) + 1, DAY(Tab_Faturamento_RJ[[#This Row],[Mês de referência para faturamento]]) ) )} -> 45901 | AJ23: =IFERROR(L23-M23,0) -> 3167.48 | AK23: =AC23-AD23 -> 0 | AL23: =K23-V23 -> 6518.61 | AN23: kaike.costa@atlasinovacoes.com.br
B24: 45818 | C24: Sim | D24: Bangu Shopping | E24: Limpeza | F24: Verzani | G24: 65 | H24: 61 | I24: 23 | J24: 0 | K24: 335112.54 | L24: 0 | M24: -3504.9 | N24: 0 | O24: 0 | P24: -2981.6 | Q24: 0 | R24: 0 | S24: 0 | T24: 0 | U24: Sim | V24: =IFERROR((K24+M24+R24+S24+T24+O24)+IF(U24="Sim",P24+Q24,0),(K24+R24+S24+T24)+IF(U24="Sim",P24+Q24,0)) -> 328626.04 | Y24: =126534.36/4 -> 31633.59 | Z24: 2|4 | AA24: 45809 | AB24: {=IFERROR( IF( _xlfn.XLOOKUP( 1, ( ('Condições de Faturamento'!$C$2:$C$1000 = Tab_Faturamento_RJ[[#This Row],[Unidade]]) * ('Condições de Faturamento'!$D$2:$D$1000 = Tab_Faturamento_RJ[[#This Row],[Categoria]]) * ('Condições de Faturamento'!$E$2:$E$1000 = Tab_Faturamento_RJ[[#This Row],[Fornecedor]]) ), 'Condições de Faturamento'!$F$2:$F$1000 ) = "Emissão no mês da prestação do serviço", Tab_Faturamento_RJ[[#This Row],[Mês de referência para faturamento]], DATE( YEAR(Tab_Faturamento_RJ[[#This Row],[Mês de referência para faturamento]]), MONTH(Tab_Faturamento_RJ[[#This Row],[Mês de referência para faturamento]]) + 1, DAY(Tab_Faturamento_RJ[[#This Row],[Mês de referência para faturamento]]) ) ), DATE( YEAR(Tab_Faturamento_RJ[[#This Row],[Mês de referência para faturamento]]), MONTH(Tab_Faturamento_RJ[[#This Row],[Mês de referência para faturamento]]) + 1, DAY(Tab_Faturamento_RJ[[#This Row],[Mês de referência para faturamento]]) ) )} -> 45809 | AJ24: =IFERROR(L24-M24,0) -> 3504.9 | AK24: =AC24-AD24 -> 0 | AL24: =K24-V24 -> 6486.5 | AN24: kaike.costa@atlasinovacoes.com.br
B25: 45887 | C25: Sim | D25: Bangu Shopping | E25: Manutenção | F25: GPS | G25: 29 | H25: 17 | I25: 0 | J25: 0 | K25: 137066.55 | L25: 0 | M25: 0 | N25: 0 | O25: 0 | P25: 0 | Q25: 0 | R25: 0 | S25: 0 | T25: 0 | U25: Sim | V25: =IFERROR((K25+M25+R25+S25+T25+O25)+IF(U25="Sim",P25+Q25,0),(K25+R25+S25+T25)+IF(U25="Sim",P25+Q25,0)) -> 137066.55 | AA25: 45839 | AB25: {=IFERROR( IF( _xlfn.XLOOKUP( 1, ( ('Condições de Faturamento'!$C$2:$C$1000 = Tab_Faturamento_RJ[[#This Row],[Unidade]]) * ('Condições de Faturamento'!$D$2:$D$1000 = Tab_Faturamento_RJ[[#This Row],[Categoria]]) * ('Condições de Faturamento'!$E$2:$E$1000 = Tab_Faturamento_RJ[[#This Row],[Fornecedor]]) ), 'Condições de Faturamento'!$F$2:$F$1000 ) = "Emissão no mês da prestação do serviço", Tab_Faturamento_RJ[[#This Row],[Mês de referência para faturamento]], DATE( YEAR(Tab_Faturamento_RJ[[#This Row],[Mês de referência para faturamento]]), MONTH(Tab_Faturamento_RJ[[#This Row],[Mês de referência para faturamento]]) + 1, DAY(Tab_Faturamento_RJ[[#This Row],[Mês de referência para faturamento]]) ) ), DATE( YEAR(Tab_Faturamento_RJ[[#This Row],[Mês de referência para faturamento]]), MONTH(Tab_Faturamento_RJ[[#This Row],[Mês de referência para faturamento]]) + 1, DAY(Tab_Faturamento_RJ[[#This Row],[Mês de referência para faturamento]]) ) )} -> 45839 | AJ25: =IFERROR(L25-M25,0) -> 0 | AK25: =AC25-AD25 -> 0 | AL25: =K25-V25 -> 0 | AN25: kaike.costa@atlasinovacoes.com.br
B26: 45877 | C26: Sim | D26: Bangu Shopping | E26: Limpeza | F26: Verzani | G26: 65 | H26: 60 | I26: 25 | J26: 0 | K26: 335112.54 | L26: 0 | M26: -3727.6 | N26: 0 | O26: 0 | P26: -3351.13 | Q26: 0 | R26: 0 | S26: 0 | T26: 0 | U26: Sim | V26: =IFERROR((K26+M26+R26+S26+T26+O26)+IF(U26="Sim",P26+Q26,0),(K26+R26+S26+T26)+IF(U26="Sim",P26+Q26,0)) -> 328033.81 | Y26: =126534.36/4 -> 31633.59 | Z26: 4|4 | AA26: 45870 | AB26: {=IFERROR( IF( _xlfn.XLOOKUP( 1, ( ('Condições de Faturamento'!$C$2:$C$1000 = Tab_Faturamento_RJ[[#This Row],[Unidade]]) * ('Condições de Faturamento'!$D$2:$D$1000 = Tab_Faturamento_RJ[[#This Row],[Categoria]]) * ('Condições de Faturamento'!$E$2:$E$1000 = Tab_Faturamento_RJ[[#This Row],[Fornecedor]]) ), 'Condições de Faturamento'!$F$2:$F$1000 ) = "Emissão no mês da prestação do serviço", Tab_Faturamento_RJ[[#This Row],[Mês de referência para faturamento]], DATE( YEAR(Tab_Faturamento_RJ[[#This Row],[Mês de referência para faturamento]]), MONTH(Tab_Faturamento_RJ[[#This Row],[Mês de referência para faturamento]]) + 1, DAY(Tab_Faturamento_RJ[[#This Row],[Mês de referência para faturamento]]) ) ), DATE( YEAR(Tab_Faturamento_RJ[[#This Row],[Mês de referência para faturamento]]), MONTH(Tab_Faturamento_RJ[[#This Row],[Mês de referência para faturamento]]) + 1, DAY(Tab_Faturamento_RJ[[#This Row],[Mês de referência para faturamento]]) ) )} -> 45870 | AD26: 4448.29 | AE26: 4448.29 | AJ26: =IFERROR(L26-M26,0) -> 3727.6 | AK26: =AC26-AD26 -> -4448.29 | AL26: =K26-V26 -> 7078.73 | AN26: kaike.costa@atlasinovacoes.com.br
B27: 45931 | C27: Sim | D27: Bangu Shopping | E27: Limpeza | F27: Verzani | G27: 65 | H27: 60 | I27: 21 | J27: 0 | K27: 335112.54 | M27: -2927.02 | O27: 0 | P27: -3351.13 | Q27: 0 | R27: 0 | S27: 0 | T27: 0 | U27: Sim | V27: =IFERROR((K27+M27+R27+S27+T27+O27)+IF(U27="Sim",P27+Q27,0),(K27+R27+S27+T27)+IF(U27="Sim",P27+Q27,0)) -> 328834.39 | AA27: 45931 | AB27: {=IFERROR( IF( _xlfn.XLOOKUP( 1, ( ('Condições de Faturamento'!$C$2:$C$1000 = Tab_Faturamento_RJ[[#This Row],[Unidade]]) * ('Condições de Faturamento'!$D$2:$D$1000 = Tab_Faturamento_RJ[[#This Row],[Categoria]]) * ('Condições de Faturamento'!$E$2:$E$1000 = Tab_Faturamento_RJ[[#This Row],[Fornecedor]]) ), 'Condições de Faturamento'!$F$2:$F$1000 ) = "Emissão no mês da prestação do serviço", Tab_Faturamento_RJ[[#This Row],[Mês de referência para faturamento]], DATE( YEAR(Tab_Faturamento_RJ[[#This Row],[Mês de referência para faturamento]]), MONTH(Tab_Faturamento_RJ[[#This Row],[Mês de referência para faturamento]]) + 1, DAY(Tab_Faturamento_RJ[[#This Row],[Mês de referência para faturamento]]) ) ), DATE( YEAR(Tab_Faturamento_RJ[[#This Row],[Mês de referência para faturamento]]), MONTH(Tab_Faturamento_RJ[[#This Row],[Mês de referência para faturamento]]) + 1, DAY(Tab_Faturamento_RJ[[#This Row],[Mês de referência para faturamento]]) ) )} -> 45931 | AJ27: =IFERROR(L27-M27,0) -> 2927.02 | AK27: =AC27-AD27 -> 0 | AL27: =K27-V27 -> 6278.15 | AN27: kaike.costa@atlasinovacoes.com.br
D28: Bangu Shopping | E28: Limpeza | F28: Verzani | G28: 65 | H28: 60 | V28: =IFERROR((K28+M28+R28+S28+T28+O28)+IF(U28="Sim",P28+Q28,0),(K28+R28+S28+T28)+IF(U28="Sim",P28+Q28,0)) -> 0 | AA28: 45962 | AB28: {=IFERROR( IF( _xlfn.XLOOKUP( 1, ( ('Condições de Faturamento'!$C$2:$C$1000 = Tab_Faturamento_RJ[[#This Row],[Unidade]]) * ('Condições de Faturamento'!$D$2:$D$1000 = Tab_Faturamento_RJ[[#This Row],[Categoria]]) * ('Condições de Faturamento'!$E$2:$E$1000 = Tab_Faturamento_RJ[[#This Row],[Fornecedor]]) ), 'Condições de Faturamento'!$F$2:$F$1000 ) = "Emissão no mês da prestação do serviço", Tab_Faturamento_RJ[[#This Row],[Mês de referência para faturamento]], DATE( YEAR(Tab_Faturamento_RJ[[#This Row],[Mês de referência para faturamento]]), MONTH(Tab_Faturamento_RJ[[#This Row],[Mês de referência para faturamento]]) + 1, DAY(Tab_Faturamento_RJ[[#This Row],[Mês de referência para faturamento]]) ) ), DATE( YEAR(Tab_Faturamento_RJ[[#This Row],[Mês de referência para faturamento]]), MONTH(Tab_Faturamento_RJ[[#This Row],[Mês de referência para faturamento]]) + 1, DAY(Tab_Faturamento_RJ[[#This Row],[Mês de referência para faturamento]]) ) )} -> 45962 | AJ28: =IFERROR(L28-M28,0) -> 0 | AK28: =AC28-AD28 -> 0 | AL28: =K28-V28 -> 0 | AN28: kaike.costa@atlasinovacoes.com.br
D29: Bangu Shopping | E29: Limpeza | F29: Verzani | G29: 65 | H29: 60 | V29: =IFERROR((K29+M29+R29+S29+T29+O29)+IF(U29="Sim",P29+Q29,0),(K29+R29+S29+T29)+IF(U29="Sim",P29+Q29,0)) -> 0 | AA29: 45992 | AB29: {=IFERROR( IF( _xlfn.XLOOKUP( 1, ( ('Condições de Faturamento'!$C$2:$C$1000 = Tab_Faturamento_RJ[[#This Row],[Unidade]]) * ('Condições de Faturamento'!$D$2:$D$1000 = Tab_Faturamento_RJ[[#This Row],[Categoria]]) * ('Condições de Faturamento'!$E$2:$E$1000 = Tab_Faturamento_RJ[[#This Row],[Fornecedor]]) ), 'Condições de Faturamento'!$F$2:$F$1000 ) = "Emissão no mês da prestação do serviço", Tab_Faturamento_RJ[[#This Row],[Mês de referência para faturamento]], DATE( YEAR(Tab_Faturamento_RJ[[#This Row],[Mês de referência para faturamento]]), MONTH(Tab_Faturamento_RJ[[#This Row],[Mês de referência para faturamento]]) + 1, DAY(Tab_Faturamento_RJ[[#This Row],[Mês de referência para faturamento]]) ) ), DATE( YEAR(Tab_Faturamento_RJ[[#This Row],[Mês de referência para faturamento]]), MONTH(Tab_Faturamento_RJ[[#This Row],[Mês de referência para faturamento]]) + 1, DAY(Tab_Faturamento_RJ[[#This Row],[Mês de referência para faturamento]]) ) )} -> 45992 | AJ29: =IFERROR(L29-M29,0) -> 0 | AK29: =AC29-AD29 -> 0 | AL29: =K29-V29 -> 0 | AN29: kaike.costa@atlasinovacoes.com.br
C30: Não | D30: Bangu Shopping | E30: Manutenção | F30: GPS | G30: 29 | H30: 17 | I30: Informação pendente | J30: Informação pendente | K30: 130282.08 | L30: 0 | M30: Informação pendente | N30: 0 | O30: Informação pendente | P30: 0 | Q30: 0 | R30: 0 | S30: 0 | T30: 0 | V30: =IFERROR((K30+M30+R30+S30+T30+O30)+IF(U30="Sim",P30+Q30,0),(K30+R30+S30+T30)+IF(U30="Sim",P30+Q30,0)) -> 130282.08 | AA30: 45658 | AB30: {=IFERROR( IF( _xlfn.XLOOKUP( 1, ( ('Condições de Faturamento'!$C$2:$C$1000 = Tab_Faturamento_RJ[[#This Row],[Unidade]]) * ('Condições de Faturamento'!$D$2:$D$1000 = Tab_Faturamento_RJ[[#This Row],[Categoria]]) * ('Condições de Faturamento'!$E$2:$E$1000 = Tab_Faturamento_RJ[[#This Row],[Fornecedor]]) ), 'Condições de Faturamento'!$F$2:$F$1000 ) = "Emissão no mês da prestação do serviço", Tab_Faturamento_RJ[[#This Row],[Mês de referência para faturamento]], DATE( YEAR(Tab_Faturamento_RJ[[#This Row],[Mês de referência para faturamento]]), MONTH(Tab_Faturamento_RJ[[#This Row],[Mês de referência para faturamento]]) + 1, DAY(Tab_Faturamento_RJ[[#This Row],[Mês de referência para faturamento]]) ) ), DATE( YEAR(Tab_Faturamento_RJ[[#This Row],[Mês de referência para faturamento]]), MONTH(Tab_Faturamento_RJ[[#This Row],[Mês de referência para faturamento]]) + 1, DAY(Tab_Faturamento_RJ[[#This Row],[Mês de referência para faturamento]]) ) )} -> 45658 | AC30: 242.57 | AD30: 242.57 | AJ30: =IFERROR(L30-M30,0) -> 0 | AK30: =AC30-AD30 -> 0 | AL30: =K30-V30 -> 0 | AN30: kaike.costa@atlasinovacoes.com.br
C31: Não | D31: Bangu Shopping | E31: Manutenção | F31: GPS | G31: 29 | H31: 17 | I31: Informação pendente | J31: Informação pendente | K31: 130282.08 | L31: 0 | M31: Informação pendente | N31: 0 | O31: Informação pendente | P31: 0 | Q31: 0 | R31: 0 | S31: 0 | T31: 0 | V31: =IFERROR((K31+M31+R31+S31+T31+O31)+IF(U31="Sim",P31+Q31,0),(K31+R31+S31+T31)+IF(U31="Sim",P31+Q31,0)) -> 130282.08 | AA31: 45689 | AB31: {=IFERROR( IF( _xlfn.XLOOKUP( 1, ( ('Condições de Faturamento'!$C$2:$C$1000 = Tab_Faturamento_RJ[[#This Row],[Unidade]]) * ('Condições de Faturamento'!$D$2:$D$1000 = Tab_Faturamento_RJ[[#This Row],[Categoria]]) * ('Condições de Faturamento'!$E$2:$E$1000 = Tab_Faturamento_RJ[[#This Row],[Fornecedor]]) ), 'Condições de Faturamento'!$F$2:$F$1000 ) = "Emissão no mês da prestação do serviço", Tab_Faturamento_RJ[[#This Row],[Mês de referência para faturamento]], DATE( YEAR(Tab_Faturamento_RJ[[#This Row],[Mês de referência para faturamento]]), MONTH(Tab_Faturamento_RJ[[#This Row],[Mês de referência para faturamento]]) + 1, DAY(Tab_Faturamento_RJ[[#This Row],[Mês de referência para faturamento]]) ) ), DATE( YEAR(Tab_Faturamento_RJ[[#This Row],[Mês de referência para faturamento]]), MONTH(Tab_Faturamento_RJ[[#This Row],[Mês de referência para faturamento]]) + 1, DAY(Tab_Faturamento_RJ[[#This Row],[Mês de referência para faturamento]]) ) )} -> 45689 | AJ31: =IFERROR(L31-M31,0) -> 0 | AK31: =AC31-AD31 -> 0 | AL31: =K31-V31 -> 0 | AN31: kaike.costa@atlasinovacoes.com.br
C32: Não | D32: Bangu Shopping | E32: Manutenção | F32: GPS | G32: 29 | H32: 17 | I32: 0 | J32: 0 | K32: 130282.08 | L32: 0 | M32: 0 | N32: 0 | O32: 0 | P32: 0 | Q32: 0 | R32: 0 | S32: 0 | T32: 0 | U32: Sim | V32: =IFERROR((K32+M32+R32+S32+T32+O32)+IF(U32="Sim",P32+Q32,0),(K32+R32+S32+T32)+IF(U32="Sim",P32+Q32,0)) -> 130282.08 | AA32: 45717 | AB32: {=IFERROR( IF( _xlfn.XLOOKUP( 1, ( ('Condições de Faturamento'!$C$2:$C$1000 = Tab_Faturamento_RJ[[#This Row],[Unidade]]) * ('Condições de Faturamento'!$D$2:$D$1000 = Tab_Faturamento_RJ[[#This Row],[Categoria]]) * ('Condições de Faturamento'!$E$2:$E$1000 = Tab_Faturamento_RJ[[#This Row],[Fornecedor]]) ), 'Condições de Faturamento'!$F$2:$F$1000 ) = "Emissão no mês da prestação do serviço", Tab_Faturamento_RJ[[#This Row],[Mês de referência para faturamento]], DATE( YEAR(Tab_Faturamento_RJ[[#This Row],[Mês de referência para faturamento]]), MONTH(Tab_Faturamento_RJ[[#This Row],[Mês de referência para faturamento]]) + 1, DAY(Tab_Faturamento_RJ[[#This Row],[Mês de referência para faturamento]]) ) ), DATE( YEAR(Tab_Faturamento_RJ[[#This Row],[Mês de referência para faturamento]]), MONTH(Tab_Faturamento_RJ[[#This Row],[Mês de referência para faturamento]]) + 1, DAY(Tab_Faturamento_RJ[[#This Row],[Mês de referência para faturamento]]) ) )} -> 45717 | AC32: 1548.2 | AD32: 1548.2 | AJ32: =IFERROR(L32-M32,0) -> 0 | AK32: =AC32-AD32 -> 0 | AL32: =K32-V32 -> 0 | AN32: kaike.costa@atlasinovacoes.com.br
C33: Não | D33: Bangu Shopping | E33: Manutenção | F33: GPS | G33: 29 | H33: 17 | I33: Informação pendente | J33: Informação pendente | K33: 130282.08 | L33: 0 | M33: Informação pendente | N33: 0 | O33: Informação pendente | P33: Preenchimento pendente | Q33: 0 | R33: 0 | S33: 0 | T33: 0 | V33: =IFERROR((K33+M33+R33+S33+T33+O33)+IF(U33="Sim",P33+Q33,0),(K33+R33+S33+T33)+IF(U33="Sim",P33+Q33,0)) -> 130282.08 | AA33: 45748 | AB33: {=IFERROR( IF( _xlfn.XLOOKUP( 1, ( ('Condições de Faturamento'!$C$2:$C$1000 = Tab_Faturamento_RJ[[#This Row],[Unidade]]) * ('Condições de Faturamento'!$D$2:$D$1000 = Tab_Faturamento_RJ[[#This Row],[Categoria]]) * ('Condições de Faturamento'!$E$2:$E$1000 = Tab_Faturamento_RJ[[#This Row],[Fornecedor]]) ), 'Condições de Faturamento'!$F$2:$F$1000 ) = "Emissão no mês da prestação do serviço", Tab_Faturamento_RJ[[#This Row],[Mês de referência para faturamento]], DATE( YEAR(Tab_Faturamento_RJ[[#This Row],[Mês de referência para faturamento]]), MONTH(Tab_Faturamento_RJ[[#This Row],[Mês de referência para faturamento]]) + 1, DAY(Tab_Faturamento_RJ[[#This Row],[Mês de referência para faturamento]]) ) ), DATE( YEAR(Tab_Faturamento_RJ[[#This Row],[Mês de referência para faturamento]]), MONTH(Tab_Faturamento_RJ[[#This Row],[Mês de referência para faturamento]]) + 1, DAY(Tab_Faturamento_RJ[[#This Row],[Mês de referência para faturamento]]) ) )} -> 45748 | AC33: 4724.23 | AD33: 4724.23 | AE33: 4505.88 | AJ33: =IFERROR(L33-M33,0) -> 0 | AK33: =AC33-AD33 -> 0 | AL33: =K33-V33 -> 0 | AN33: kaike.costa@atlasinovacoes.com.br
C34: Não | D34: Bangu Shopping | E34: Manutenção | F34: GPS | G34: 29 | H34: 17 | I34: 0 | J34: 0 | K34: 130282.08 | L34: 0 | M34: 0 | N34: 0 | O34: 0 | P34: 0 | Q34: 0 | R34: 0 | S34: 0 | T34: 0 | U34: Não | V34: =IFERROR((K34+M34+R34+S34+T34+O34)+IF(U34="Sim",P34+Q34,0),(K34+R34+S34+T34)+IF(U34="Sim",P34+Q34,0)) -> 130282.08 | AA34: 45778 | AB34: {=IFERROR( IF( _xlfn.XLOOKUP( 1, ( ('Condições de Faturamento'!$C$2:$C$1000 = Tab_Faturamento_RJ[[#This Row],[Unidade]]) * ('Condições de Faturamento'!$D$2:$D$1000 = Tab_Faturamento_RJ[[#This Row],[Categoria]]) * ('Condições de Faturamento'!$E$2:$E$1000 = Tab_Faturamento_RJ[[#This Row],[Fornecedor]]) ), 'Condições de Faturamento'!$F$2:$F$1000 ) = "Emissão no mês da prestação do serviço", Tab_Faturamento_RJ[[#This Row],[Mês de referência para faturamento]], DATE( YEAR(Tab_Faturamento_RJ[[#This Row],[Mês de referência para faturamento]]), MONTH(Tab_Faturamento_RJ[[#This Row],[Mês de referência para faturamento]]) + 1, DAY(Tab_Faturamento_RJ[[#This Row],[Mês de referência para faturamento]]) ) ), DATE( YEAR(Tab_Faturamento_RJ[[#This Row],[Mês de referência para faturamento]]), MONTH(Tab_Faturamento_RJ[[#This Row],[Mês de referência para faturamento]]) + 1, DAY(Tab_Faturamento_RJ[[#This Row],[Mês de referência para faturamento]]) ) )} -> 45778 | AJ34: =IFERROR(L34-M34,0) -> 0 | AK34: =AC34-AD34 -> 0 | AL34: =K34-V34 -> 0 | AN34: kaike.costa@atlasinovacoes.com.br
C35: Não | D35: Bangu Shopping | E35: Manutenção | F35: GPS | G35: 29 | H35: 17 | I35: Informação pendente | J35: Informação pendente | K35: 130282.08 | L35: 0 | M35: Informação pendente | N35: 0 | O35: Informação pendente | P35: Preenchimento pendente | Q35: 0 | R35: 0 | S35: 0 | T35: 0 | U35: Não | V35: =IFERROR((K35+M35+R35+S35+T35+O35)+IF(U35="Sim",P35+Q35,0),(K35+R35+S35+T35)+IF(U35="Sim",P35+Q35,0)) -> 130282.08 | AA35: 45809 | AB35: {=IFERROR( IF( _xlfn.XLOOKUP( 1, ( ('Condições de Faturamento'!$C$2:$C$1000 = Tab_Faturamento_RJ[[#This Row],[Unidade]]) * ('Condições de Faturamento'!$D$2:$D$1000 = Tab_Faturamento_RJ[[#This Row],[Categoria]]) * ('Condições de Faturamento'!$E$2:$E$1000 = Tab_Faturamento_RJ[[#This Row],[Fornecedor]]) ), 'Condições de Faturamento'!$F$2:$F$1000 ) = "Emissão no mês da prestação do serviço", Tab_Faturamento_RJ[[#This Row],[Mês de referência para faturamento]], DATE( YEAR(Tab_Faturamento_RJ[[#This Row],[Mês de referência para faturamento]]), MONTH(Tab_Faturamento_RJ[[#This Row],[Mês de referência para faturamento]]) + 1, DAY(Tab_Faturamento_RJ[[#This Row],[Mês de referência para faturamento]]) ) ), DATE( YEAR(Tab_Faturamento_RJ[[#This Row],[Mês de referência para faturamento]]), MONTH(Tab_Faturamento_RJ[[#This Row],[Mês de referência para faturamento]]) + 1, DAY(Tab_Faturamento_RJ[[#This Row],[Mês de referência para faturamento]]) ) )} -> 45809 | AJ35: =IFERROR(L35-M35,0) -> 0 | AK35: =AC35-AD35 -> 0 | AL35: =K35-V35 -> 0 | AN35: kaike.costa@atlasinovacoes.com.br
